[QC2019-08-07 00:06:02] WARN [nioEventLoopGroup-2-1] io.netty.util.internal.logging.Slf4JLogger.warn(151) | An exceptionCaught() event was fired, and it reached at the tail of the pipeline. It usually means the last handler in the pipeline did not handle the exception.
java.io.IOException: 远程主机强迫关闭了一个现有的连接。
	at sun.nio.ch.SocketDispatcher.read0(Native Method)
	at sun.nio.ch.SocketDispatcher.read(Unknown Source)
	at sun.nio.ch.IOUtil.readIntoNativeBuffer(Unknown Source)
	at sun.nio.ch.IOUtil.read(Unknown Source)
	at sun.nio.ch.SocketChannelImpl.read(Unknown Source)
	at io.netty.buffer.PooledUnsafeDirectByteBuf.setBytes(PooledUnsafeDirectByteBuf.java:288)
	at io.netty.buffer.AbstractByteBuf.writeBytes(AbstractByteBuf.java:1100)
	at io.netty.channel.socket.nio.NioSocketChannel.doReadBytes(NioSocketChannel.java:367)
	at io.netty.channel.nio.AbstractNioByteChannel$NioByteUnsafe.read(AbstractNioByteChannel.java:118)
	at io.netty.channel.nio.NioEventLoop.processSelectedKey(NioEventLoop.java:610)
	at io.netty.channel.nio.NioEventLoop.processSelectedKeysOptimized(NioEventLoop.java:551)
	at io.netty.channel.nio.NioEventLoop.processSelectedKeys(NioEventLoop.java:465)
	at io.netty.channel.nio.NioEventLoop.run(NioEventLoop.java:437)
	at io.netty.util.concurrent.SingleThreadEventExecutor$5.run(SingleThreadEventExecutor.java:873)
	at io.netty.util.concurrent.DefaultThreadFactory$DefaultRunnableDecorator.run(DefaultThreadFactory.java:144)
	at java.lang.Thread.run(Unknown Source)
[QC2019-08-07 00:45:03] WARN [nioEventLoopGroup-2-1] io.netty.util.internal.logging.Slf4JLogger.warn(151) | An exceptionCaught() event was fired, and it reached at the tail of the pipeline. It usually means the last handler in the pipeline did not handle the exception.
java.io.IOException: 远程主机强迫关闭了一个现有的连接。
	at sun.nio.ch.SocketDispatcher.read0(Native Method)
	at sun.nio.ch.SocketDispatcher.read(Unknown Source)
	at sun.nio.ch.IOUtil.readIntoNativeBuffer(Unknown Source)
	at sun.nio.ch.IOUtil.read(Unknown Source)
	at sun.nio.ch.SocketChannelImpl.read(Unknown Source)
	at io.netty.buffer.PooledUnsafeDirectByteBuf.setBytes(PooledUnsafeDirectByteBuf.java:288)
	at io.netty.buffer.AbstractByteBuf.writeBytes(AbstractByteBuf.java:1100)
	at io.netty.channel.socket.nio.NioSocketChannel.doReadBytes(NioSocketChannel.java:367)
	at io.netty.channel.nio.AbstractNioByteChannel$NioByteUnsafe.read(AbstractNioByteChannel.java:118)
	at io.netty.channel.nio.NioEventLoop.processSelectedKey(NioEventLoop.java:610)
	at io.netty.channel.nio.NioEventLoop.processSelectedKeysOptimized(NioEventLoop.java:551)
	at io.netty.channel.nio.NioEventLoop.processSelectedKeys(NioEventLoop.java:465)
	at io.netty.channel.nio.NioEventLoop.run(NioEventLoop.java:437)
	at io.netty.util.concurrent.SingleThreadEventExecutor$5.run(SingleThreadEventExecutor.java:873)
	at io.netty.util.concurrent.DefaultThreadFactory$DefaultRunnableDecorator.run(DefaultThreadFactory.java:144)
	at java.lang.Thread.run(Unknown Source)
[QC2019-08-07 00:47:24] WARN [nioEventLoopGroup-2-1] io.netty.util.internal.logging.Slf4JLogger.warn(151) | An exceptionCaught() event was fired, and it reached at the tail of the pipeline. It usually means the last handler in the pipeline did not handle the exception.
java.io.IOException: 远程主机强迫关闭了一个现有的连接。
	at sun.nio.ch.SocketDispatcher.read0(Native Method)
	at sun.nio.ch.SocketDispatcher.read(Unknown Source)
	at sun.nio.ch.IOUtil.readIntoNativeBuffer(Unknown Source)
	at sun.nio.ch.IOUtil.read(Unknown Source)
	at sun.nio.ch.SocketChannelImpl.read(Unknown Source)
	at io.netty.buffer.PooledUnsafeDirectByteBuf.setBytes(PooledUnsafeDirectByteBuf.java:288)
	at io.netty.buffer.AbstractByteBuf.writeBytes(AbstractByteBuf.java:1100)
	at io.netty.channel.socket.nio.NioSocketChannel.doReadBytes(NioSocketChannel.java:367)
	at io.netty.channel.nio.AbstractNioByteChannel$NioByteUnsafe.read(AbstractNioByteChannel.java:118)
	at io.netty.channel.nio.NioEventLoop.processSelectedKey(NioEventLoop.java:610)
	at io.netty.channel.nio.NioEventLoop.processSelectedKeysOptimized(NioEventLoop.java:551)
	at io.netty.channel.nio.NioEventLoop.processSelectedKeys(NioEventLoop.java:465)
	at io.netty.channel.nio.NioEventLoop.run(NioEventLoop.java:437)
	at io.netty.util.concurrent.SingleThreadEventExecutor$5.run(SingleThreadEventExecutor.java:873)
	at io.netty.util.concurrent.DefaultThreadFactory$DefaultRunnableDecorator.run(DefaultThreadFactory.java:144)
	at java.lang.Thread.run(Unknown Source)
[QC2019-08-07 00:47:56] WARN [nioEventLoopGroup-2-1] io.netty.util.internal.logging.Slf4JLogger.warn(151) | An exceptionCaught() event was fired, and it reached at the tail of the pipeline. It usually means the last handler in the pipeline did not handle the exception.
java.lang.NullPointerException
	at NettyProtobufWebsocketClient.ClassUtils.findMethod(ClassUtils.java:104)
	at NettyProtobufWebsocketClient.ClientHandler.channelRead0(ClientHandler.java:76)
	at io.netty.channel.SimpleChannelInboundHandler.channelRead(SimpleChannelInboundHandler.java:105)
	at io.netty.channel.AbstractChannelHandlerContext.invokeChannelRead(AbstractChannelHandlerContext.java:372)
	at io.netty.channel.AbstractChannelHandlerContext.invokeChannelRead(AbstractChannelHandlerContext.java:358)
	at io.netty.channel.AbstractChannelHandlerContext.fireChannelRead(AbstractChannelHandlerContext.java:350)
	at NettyProtobufWebsocketClient.ProtoDecoder.channelRead(ProtoDecoder.java:41)
	at io.netty.channel.AbstractChannelHandlerContext.invokeChannelRead(AbstractChannelHandlerContext.java:372)
	at io.netty.channel.AbstractChannelHandlerContext.invokeChannelRead(AbstractChannelHandlerContext.java:358)
	at io.netty.channel.AbstractChannelHandlerContext.fireChannelRead(AbstractChannelHandlerContext.java:350)
	at io.netty.handler.codec.ByteToMessageDecoder.fireChannelRead(ByteToMessageDecoder.java:293)
	at io.netty.handler.codec.ByteToMessageDecoder.channelRead(ByteToMessageDecoder.java:267)
	at io.netty.channel.AbstractChannelHandlerContext.invokeChannelRead(AbstractChannelHandlerContext.java:372)
	at io.netty.channel.AbstractChannelHandlerContext.invokeChannelRead(AbstractChannelHandlerContext.java:358)
	at io.netty.channel.AbstractChannelHandlerContext.fireChannelRead(AbstractChannelHandlerContext.java:350)
	at io.netty.channel.DefaultChannelPipeline$HeadContext.channelRead(DefaultChannelPipeline.java:1334)
	at io.netty.channel.AbstractChannelHandlerContext.invokeChannelRead(AbstractChannelHandlerContext.java:372)
	at io.netty.channel.AbstractChannelHandlerContext.invokeChannelRead(AbstractChannelHandlerContext.java:358)
	at io.netty.channel.DefaultChannelPipeline.fireChannelRead(DefaultChannelPipeline.java:926)
	at io.netty.channel.nio.AbstractNioByteChannel$NioByteUnsafe.read(AbstractNioByteChannel.java:129)
	at io.netty.channel.nio.NioEventLoop.processSelectedKey(NioEventLoop.java:610)
	at io.netty.channel.nio.NioEventLoop.processSelectedKeysOptimized(NioEventLoop.java:551)
	at io.netty.channel.nio.NioEventLoop.processSelectedKeys(NioEventLoop.java:465)
	at io.netty.channel.nio.NioEventLoop.run(NioEventLoop.java:437)
	at io.netty.util.concurrent.SingleThreadEventExecutor$5.run(SingleThreadEventExecutor.java:873)
	at io.netty.util.concurrent.DefaultThreadFactory$DefaultRunnableDecorator.run(DefaultThreadFactory.java:144)
	at java.lang.Thread.run(Unknown Source)
[QC2019-08-07 01:01:54] WARN [nioEventLoopGroup-2-1] io.netty.util.internal.logging.Slf4JLogger.warn(151) | An exceptionCaught() event was fired, and it reached at the tail of the pipeline. It usually means the last handler in the pipeline did not handle the exception.
java.io.IOException: 远程主机强迫关闭了一个现有的连接。
	at sun.nio.ch.SocketDispatcher.read0(Native Method)
	at sun.nio.ch.SocketDispatcher.read(Unknown Source)
	at sun.nio.ch.IOUtil.readIntoNativeBuffer(Unknown Source)
	at sun.nio.ch.IOUtil.read(Unknown Source)
	at sun.nio.ch.SocketChannelImpl.read(Unknown Source)
	at io.netty.buffer.PooledUnsafeDirectByteBuf.setBytes(PooledUnsafeDirectByteBuf.java:288)
	at io.netty.buffer.AbstractByteBuf.writeBytes(AbstractByteBuf.java:1100)
	at io.netty.channel.socket.nio.NioSocketChannel.doReadBytes(NioSocketChannel.java:367)
	at io.netty.channel.nio.AbstractNioByteChannel$NioByteUnsafe.read(AbstractNioByteChannel.java:118)
	at io.netty.channel.nio.NioEventLoop.processSelectedKey(NioEventLoop.java:610)
	at io.netty.channel.nio.NioEventLoop.processSelectedKeysOptimized(NioEventLoop.java:551)
	at io.netty.channel.nio.NioEventLoop.processSelectedKeys(NioEventLoop.java:465)
	at io.netty.channel.nio.NioEventLoop.run(NioEventLoop.java:437)
	at io.netty.util.concurrent.SingleThreadEventExecutor$5.run(SingleThreadEventExecutor.java:873)
	at io.netty.util.concurrent.DefaultThreadFactory$DefaultRunnableDecorator.run(DefaultThreadFactory.java:144)
	at java.lang.Thread.run(Unknown Source)
[QC2019-08-07 01:02:27] WARN [nioEventLoopGroup-2-1] io.netty.util.internal.logging.Slf4JLogger.warn(151) | An exceptionCaught() event was fired, and it reached at the tail of the pipeline. It usually means the last handler in the pipeline did not handle the exception.
java.io.IOException: 远程主机强迫关闭了一个现有的连接。
	at sun.nio.ch.SocketDispatcher.read0(Native Method)
	at sun.nio.ch.SocketDispatcher.read(Unknown Source)
	at sun.nio.ch.IOUtil.readIntoNativeBuffer(Unknown Source)
	at sun.nio.ch.IOUtil.read(Unknown Source)
	at sun.nio.ch.SocketChannelImpl.read(Unknown Source)
	at io.netty.buffer.PooledUnsafeDirectByteBuf.setBytes(PooledUnsafeDirectByteBuf.java:288)
	at io.netty.buffer.AbstractByteBuf.writeBytes(AbstractByteBuf.java:1100)
	at io.netty.channel.socket.nio.NioSocketChannel.doReadBytes(NioSocketChannel.java:367)
	at io.netty.channel.nio.AbstractNioByteChannel$NioByteUnsafe.read(AbstractNioByteChannel.java:118)
	at io.netty.channel.nio.NioEventLoop.processSelectedKey(NioEventLoop.java:610)
	at io.netty.channel.nio.NioEventLoop.processSelectedKeysOptimized(NioEventLoop.java:551)
	at io.netty.channel.nio.NioEventLoop.processSelectedKeys(NioEventLoop.java:465)
	at io.netty.channel.nio.NioEventLoop.run(NioEventLoop.java:437)
	at io.netty.util.concurrent.SingleThreadEventExecutor$5.run(SingleThreadEventExecutor.java:873)
	at io.netty.util.concurrent.DefaultThreadFactory$DefaultRunnableDecorator.run(DefaultThreadFactory.java:144)
	at java.lang.Thread.run(Unknown Source)
[QC2019-08-07 23:38:59] WARN [nioEventLoopGroup-2-1] io.netty.util.internal.logging.Slf4JLogger.warn(151) | An exceptionCaught() event was fired, and it reached at the tail of the pipeline. It usually means the last handler in the pipeline did not handle the exception.
java.io.IOException: 远程主机强迫关闭了一个现有的连接。
	at sun.nio.ch.SocketDispatcher.read0(Native Method)
	at sun.nio.ch.SocketDispatcher.read(Unknown Source)
	at sun.nio.ch.IOUtil.readIntoNativeBuffer(Unknown Source)
	at sun.nio.ch.IOUtil.read(Unknown Source)
	at sun.nio.ch.SocketChannelImpl.read(Unknown Source)
	at io.netty.buffer.PooledUnsafeDirectByteBuf.setBytes(PooledUnsafeDirectByteBuf.java:288)
	at io.netty.buffer.AbstractByteBuf.writeBytes(AbstractByteBuf.java:1100)
	at io.netty.channel.socket.nio.NioSocketChannel.doReadBytes(NioSocketChannel.java:367)
	at io.netty.channel.nio.AbstractNioByteChannel$NioByteUnsafe.read(AbstractNioByteChannel.java:118)
	at io.netty.channel.nio.NioEventLoop.processSelectedKey(NioEventLoop.java:610)
	at io.netty.channel.nio.NioEventLoop.processSelectedKeysOptimized(NioEventLoop.java:551)
	at io.netty.channel.nio.NioEventLoop.processSelectedKeys(NioEventLoop.java:465)
	at io.netty.channel.nio.NioEventLoop.run(NioEventLoop.java:437)
	at io.netty.util.concurrent.SingleThreadEventExecutor$5.run(SingleThreadEventExecutor.java:873)
	at io.netty.util.concurrent.DefaultThreadFactory$DefaultRunnableDecorator.run(DefaultThreadFactory.java:144)
	at java.lang.Thread.run(Unknown Source)
